Workbook

Sheet Setup ⚙️
B1: Setup Spreadsheet
AJ3: ICONS
AJ4: ✅ | AK4: ❎ | AL4: ❌ | AM4: ✔️ | AN4: ⏳ | AO4: ⛔️
B5: Status Label Names | P5: Members | AD5: Holidays | AJ5: 🚩 | AK5: ⚠️ | AL5: ❗️ | AM5: 💲 | AN5: 💰 | AO5: 📌 | AQ5: Status | BA5: Members
AJ6: 🔴 | AK6: 🟠 | AL6: 🟡 | AM6: 🟢 | AN6: 🔵 | AO6: 🟣 | AQ6: =IF(ISBLANK(C7),E7, CONCATENATE(C7," ",E7)) -> Completata | BA6: =Q8 -> 0
E7: Completata | Q7: Name | AE7: Holiday Name | AF7: Date | AJ7: ⚫️ | AK7: 🟥 | AL7: 🟧 | AM7: 🟨 | AN7: 🟩 | AO7: 🟦 | AQ7: =IF(ISBLANK(C8),E8, CONCATENATE(C8," ",E8)) -> Programmata | BA7: =Q9 -> 0
E8: Programmata | AJ8: 🟪 | AK8: ⬛️ | AL8: ❤️ | AM8: 💚 | AN8: 💙 | AO8: 💜 | AQ8: =IF(ISBLANK(C9),E9, CONCATENATE(C9," ",E9)) -> In corso | BA8: =Q10 -> 0
E9: In corso | AJ9: 🧒 | AK9: 👨 | AL9: 👧 | AM9: 🙋🏻‍♀️ | AN9: 🙋🏻 | AO9: 🙋🏻‍♂️ | AQ9: =IF(ISBLANK(C10),E10, CONCATENATE(C10," ",E10)) -> Da pianificare | BA9: =Q11 -> 0
E10: Da pianificare | AJ10: 🧷 | AK10: ✏️ | AL10: 📝 | AM10: 📙 | AN10: 📍 | AO10: 😍 | AQ10: =IF(ISBLANK(C11),E11, CONCATENATE(C11," ",E11)) -> Da iniziare | BA10: =Q12 -> 0
E11: Da iniziare | AJ11: 🙂 | AK11: 📢 | AL11: 📣 | AM11: 🔕 | AN11: 🕘 | AO11: 💥 | AQ11: =IF(ISBLANK(C12),E12, CONCATENATE(C12," ",E12)) -> In Revisione | BA11: =Q13 -> 0
E12: In Revisione | AJ12: 🕶️ | AK12: 🔓 | AL12: ☀️ | AM12: 😎 | AN12: 🥰 | AO12: 👥 | BA12: =Q14 -> 0
AJ13: 👤 | AK13: 💤 | AL13: 📙 | AM13: 📅 | BA13: =Q15 -> 0
BA14: =Q16 -> 0
B15: Priority Level Label Names | BA15: =Q17 -> 0
BA16: =Q18 -> 0
C17: 📅 | E17: Bassa Priorità | AQ17: Priority Level Label Names | BA17: =Q19 -> 0
C18: ✏️ | E18: Media priorità | AQ18: =IF(ISBLANK(C17),E17, CONCATENATE(C17," ",E17)) -> 📅 Bassa Priorità | BA18: =Q20 -> 0
C19: ⚠️ | E19: Alta priorità | AQ19: =IF(ISBLANK(C18),E18, CONCATENATE(C18," ",E18)) -> ✏️ Media priorità | BA19: =Q21 -> 0
C20: 📢 | E20: Urgente | AQ20: =IF(ISBLANK(C19),E19, CONCATENATE(C19," ",E19)) -> ⚠️ Alta priorità | BA20: =Q22 -> 0
C21: ❗️ | E21: Critica | AQ21: =IF(ISBLANK(C20),E20, CONCATENATE(C20," ",E20)) -> 📢 Urgente | BA21: =Q23 -> 0
AQ22: =IF(ISBLANK(C21),E21, CONCATENATE(C21," ",E21)) -> ❗️ Critica | BA22: =Q24 -> 0
BA23: =Q25 -> 0
B24: Weekend Option | AQ24: Include Weekends On Chart | BA24: =Q26 -> 0
AQ25: Show Weekdays Only | BA25: =Q27 -> 0
C26: Show Weekdays Only
AQ27: Sunday
AQ28: Monday
B30: Weekly Start Day
C32: Monday

Sheet Gantt Chart 📅
G1: =IF('Setup ⚙️'!AQ6="","Blank_Text",'Setup ⚙️'!AQ6) -> Completata | H1: =IF(D4="","","W1") | I1: =IF('Setup ⚙️'!$C$32="Monday",I$52,I$51) | J1: =IF('Setup ⚙️'!$C$32="Monday",J$52,J$51) | K1: =IF('Setup ⚙️'!$C$32="Monday",K$52,K$51) | L1: =IF('Setup ⚙️'!$C$32="Monday",L$52,L$51) | M1: =IF('Setup ⚙️'!$C$32="Monday",M$52,M$51) | N1: =IF('Setup ⚙️'!$C$32="Monday",N$52,N$51) | O1: =IF('Setup ⚙️'!$C$32="Monday",O$52,O$51) | P1: =IF('Setup ⚙️'!$C$32="Monday",P$52,P$51) | ... SC1: =IF('Setup ⚙️'!$C$32="Monday",SC$52,SC$51)
B2: Gantt | G2: =IF('Setup ⚙️'!AQ7="","Blank_Text",'Setup ⚙️'!AQ7) -> Programmata
C3: Nome del Progetto | D3: TS HR AiO | G3: =IF('Setup ⚙️'!AQ8="","Blank_Text",'Setup ⚙️'!AQ8) -> In corso | H3: =H9 -> 0 | I3: =I9 -> 2 | J3: =J9 -> 3 | K3: =K9 -> 4 | L3: =L9 -> 5 | M3: =M9 -> 6 | N3: =N9 -> 9 | O3: =O9 -> 10 | ... SC3: =SC9 -> 684
C4: Data di inizio | G4: =IF('Setup ⚙️'!AQ9="","Blank_Text",'Setup ⚙️'!AQ9) -> Da pianificare
C5: Data di fine
C6: Data odierna | D6: =TODAY() -> 46265 | G6: =IF('Setup ⚙️'!AQ11="","Blank_Text",'Setup ⚙️'!AQ11) -> In Revisione
H8: =H9 -> 0 | I8: =I9 -> 2 | J8: =J9 -> 3 | K8: =K9 -> 4 | L8: =L9 -> 5 | M8: =M9 -> 6 | N8: =N9 -> 9 | O8: =O9 -> 10 | ... SC8: =SC9 -> 684
C9: Priorità | D9: Assegnatari | E9: Stato | F9: Inizio | G9: Fine | H9: =D4 -> 0 | I9: =IF( 'Setup ⚙️'!$C$26 = "Show Weekdays Only",WORKDAY(H9,1,'Setup ⚙️'!$AF$8:$AF$51),WORKDAY.INTL(H9,1,"0000000",'Setup ⚙️'!$AF$8:$AF$51)) -> 2 | J9: =IF( 'Setup ⚙️'!$C$26 = "Show Weekdays Only",WORKDAY(I9,1,'Setup ⚙️'!$AF$8:$AF$51),WORKDAY.INTL(I9,1,"0000000",'Setup ⚙️'!$AF$8:$AF$51)) -> 3 | K9: =IF( 'Setup ⚙️'!$C$26 = "Show Weekdays Only",WORKDAY(J9,1,'Setup ⚙️'!$AF$8:$AF$51),WORKDAY.INTL(J9,1,"0000000",'Setup ⚙️'!$AF$8:$AF$51)) -> 4 | L9: =IF( 'Setup ⚙️'!$C$26 = "Show Weekdays Only",WORKDAY(K9,1,'Setup ⚙️'!$AF$8:$AF$51),WORKDAY.INTL(K9,1,"0000000",'Setup ⚙️'!$AF$8:$AF$51)) -> 5 | M9: =IF( 'Setup ⚙️'!$C$26 = "Show Weekdays Only",WORKDAY(L9,1,'Setup ⚙️'!$AF$8:$AF$51),WORKDAY.INTL(L9,1,"0000000",'Setup ⚙️'!$AF$8:$AF$51)) -> 6 | N9: =IF( 'Setup ⚙️'!$C$26 = "Show Weekdays Only",WORKDAY(M9,1,'Setup ⚙️'!$AF$8:$AF$51),WORKDAY.INTL(M9,1,"0000000",'Setup ⚙️'!$AF$8:$AF$51)) -> 9 | O9: =IF( 'Setup ⚙️'!$C$26 = "Show Weekdays Only",WORKDAY(N9,1,'Setup ⚙️'!$AF$8:$AF$51),WORKDAY.INTL(N9,1,"0000000",'Setup ⚙️'!$AF$8:$AF$51)) -> 10 | P9: =IF( 'Setup ⚙️'!$C$26 = "Show Weekdays Only",WORKDAY(O9,1,'Setup ⚙️'!$AF$8:$AF$51),WORKDAY.INTL(O9,1,"0000000",'Setup ⚙️'!$AF$8:$AF$51)) -> 11 | ... SC9: =IF( 'Setup ⚙️'!$C$26 = "Show Weekdays Only",WORKDAY(SB9,1,'Setup ⚙️'!$AF$8:$AF$51),WORKDAY.INTL(SB9,1,"0000000",'Setup ⚙️'!$AF$8:$AF$51)) -> 684
A11: Avvio e pianificazione
A12: 1.1 | B12: Firma del contratto
A13: 1.2 | B13: Kick off
A14: 1.3 | B14: Progetto Esecutivo
A15: 1.4 | B15: Definizione e validazione Gantt
A16: 1.5 | B16: Documento di Analisi per la wave 1
A17: 1.6 | B17: Documento di Collaudo
A18: 1.7 | B18: Documento di consegna
A19: Portale e Presenze:
A20: 2.1 | B20: Analisi Portale
A21: 2.2 | B21: Analisi Presenze
A22: 2.3 | B22: Configurazione
A23: 2.4 | B23: Formazione
A24: 2.5 | B24: Go Live
A25: Integrazione Payroll:
A26: 3.1 | B26: Analisi
A27: 3.2 | B27: Progettazione flussi
A28: 3.3 | B28: Configurazione
A29: 3.4 | B29: Test di integrazione | I29: {=IFERROR(_xlfn._xlws.FILTER(#REF!, (I$9 = $F29)), "")}
A30: 3.5 | B30: Parallelo | I30: {=IFERROR(_xlfn._xlws.FILTER(#REF!, (I$9 = $F30)), "")}
A31: 3.6 | B31: Go Live
A32: SSO:
A33: 4.1 | B33: Analisi
A34: 4.2 | B34: Configurazione
A35: 4.3 | B35: Formazione
A36: 4.4 | B36: Go Live
A37: Pianificazione e Timesheet:
A38: 5.1 | B38: Analisi
A39: 5.2 | B39: Configurazione
A40: 5.3 | B40: Test
A41: 5.4 | B41: Formazione
A42: 5.5 | B42: Go Live
...
